200 0.8 200 200 store
Running for N=200, p=0.8, N_sample=200, clicks_per_sample=200
Data will be saved in folder store
Obtaining 128 samples...
joblib.externals.loky.process_executor._RemoteTraceback: 
"""
Traceback (most recent call last):
  File "/opt/packages/anaconda3/lib/python3.8/site-packages/joblib/externals/loky/process_executor.py", line 431, in _process_worker
    r = call_item()
  File "/opt/packages/anaconda3/lib/python3.8/site-packages/joblib/externals/loky/process_executor.py", line 285, in __call__
    return self.fn(*self.args, **self.kwargs)
  File "/opt/packages/anaconda3/lib/python3.8/site-packages/joblib/_parallel_backends.py", line 595, in __call__
    return self.func(*args, **kwargs)
  File "/opt/packages/anaconda3/lib/python3.8/site-packages/joblib/parallel.py", line 262, in __call__
    return [func(*args, **kwargs)
  File "/opt/packages/anaconda3/lib/python3.8/site-packages/joblib/parallel.py", line 262, in <listcomp>
    return [func(*args, **kwargs)
  File "run_fermion_trajectories.py", line 55, in get_instance
    d_Np = sample_trajectory(N,
  File "/ocean/projects/dmr200016p/mathvr/home/Fermion_MIPT/functions.py", line 144, in sample_trajectory
    data['S'].append( [get_entropy(G,l) for l in range(N+1) ] )
  File "/ocean/projects/dmr200016p/mathvr/home/Fermion_MIPT/functions.py", line 144, in <listcomp>
    data['S'].append( [get_entropy(G,l) for l in range(N+1) ] )
  File "/ocean/projects/dmr200016p/mathvr/home/Fermion_MIPT/functions.py", line 69, in get_entropy
    es = eigh(sG)[0]
  File "/opt/packages/anaconda3/lib/python3.8/site-packages/scipy/linalg/decomp.py", line 604, in eigh
    raise LinAlgError(msg)
numpy.linalg.LinAlgError: Internal Error.
"""

The above exception was the direct cause of the following exception:

Traceback (most recent call last):
  File "run_fermion_trajectories.py", line 70, in <module>
    S_dat = Parallel(n_jobs=-1)(delayed(get_instance)() for i in range(N_traj))
  File "/opt/packages/anaconda3/lib/python3.8/site-packages/joblib/parallel.py", line 1061, in __call__
    self.retrieve()
  File "/opt/packages/anaconda3/lib/python3.8/site-packages/joblib/parallel.py", line 940, in retrieve
    self._output.extend(job.get(timeout=self.timeout))
  File "/opt/packages/anaconda3/lib/python3.8/site-packages/joblib/_parallel_backends.py", line 542, in wrap_future_result
    return future.result(timeout=timeout)
  File "/opt/packages/anaconda3/lib/python3.8/concurrent/futures/_base.py", line 432, in result
    return self.__get_result()
  File "/opt/packages/anaconda3/lib/python3.8/concurrent/futures/_base.py", line 388, in __get_result
    raise self._exception
numpy.linalg.LinAlgError: Internal Error.
